Workbook

Sheet Leggimi
A1: AddiOFA: conti del primo anno e dei tre anni
A3: Come si usa
A4: 1. Le ipotesi sono tutte nel foglio Ipotesi, in tre colonne: Prudente, Base, Buono.
A5: 2. Numeri in blu = ipotesi da cambiare. Numeri in nero = formule: non toccarli.
A6: 3. Le celle gialle sono le ipotesi che pesano di più: misurale con la beta e aggiornale.
A7: 4. Nel foglio Ipotesi, cella C3, scegli lo scenario mostrato nei fogli Mesi e Tre anni.
A8: 5. Il risultato è calcolato in due modi: Gestione Separata (professionista) e Commercianti (impresa). Quale vale lo decide il commercialista.
A10: Cosa contiene
A11: Ipotesi: tutte le leve, con la fonte o la nota accanto.
A12: Anno 2027: conto economico del primo anno di vendita (gennaio-dicembre 2027) nei tre scenari.
A13: Mesi: come si distribuiscono incassi e costi nei 12 mesi del 2027, scenario scelto.
A14: Tre anni: 2027-2029 con le ipotesi di crescita.
... A20: Va confermato con un commercialista prima del primo incasso.

Sheet Ipotesi
A1: Ipotesi
A3: Scenario mostrato nei fogli Mesi e Tre anni | C3: Base | D3: =IF(C3="Prudente",1,IF(C3="Buono",3,2)) | E3: ← numero dello scenario (1-3), usato dalle formule
A5: Ipotesi | C5: Prudente | D5: Base | E5: Buono | F5: Fonte o nota
A7: Mercato del recupero (studenti con OFA di inglese)
A8: Immatricolati l'anno ai corsi in italiano | C8: 7000 | D8: 7000 | E8: 7000 | F8: USTAT: 7.820 immatricolati 2024/25, meno circa 800 nei corsi in inglese (stima).
A9: Quota con OFA di inglese | C9: 0.21 | D9: 0.22 | E9: 0.23 | F9: Graduatorie 2022-2026: 21-25 % degli ammessi con il dato; sondaggio Gestionale 23,5 %.
A10: Quota che lo toglie con un certificato B1 già posseduto | C10: 0.3 | D10: 0.22 | E10: 0.15 | F10: Ipotesi: non esiste un dato pubblico. Da misurare con un sondaggio.
A11: Studenti degli anni precedenti ancora con l'OFA | C11: 100 | D11: 200 | E11: 300 | F11: Ipotesi.
A12: Quota del mercato che finisce il diagnostico gratuito | C12: 0.25 | D12: 0.4 | E12: 0.55 | F12: Ipotesi chiave: dipende da accordo PoliNetwork, Google e passaparola.
A13: Conversione a pagamento di chi ha finito il diagnostico | C13: 0.05 | D13: 0.09 | E13: 0.13 | F13: RevenueCat 2026: mediana 2,1 %, quartile alto 4,5 % sui download; qui il bisogno è acuto.
A15: Mercato della prevenzione (candidati al test d'ingresso)
A16: Candidati l'anno al test d'ingresso (TENG incluso) | C16: 14000 | D16: 14000 | E16: 14000 | F16: Graduatorie 2026: 14.162 candidati unici.
A17: Quota dei candidati che prova l'app | C17: 0.01 | D17: 0.025 | E17: 0.04 | F17: Ipotesi: solo contenuti gratuiti (YouTube, Google), primo anno.
A18: Conversione a pagamento dei candidati che provano | C18: 0.03 | D18: 0.05 | E18: 0.08 | F18: Ipotesi: bisogno meno urgente del recupero.
A20: Prezzi e mix
A21: Prezzo del Pass | C21: 14.99 | D21: 14.99 | E21: 14.99 | F21: Proposta del documento.
A22: Prezzo di lancio | C22: 9.99 | D22: 9.99 | E22: 9.99 | F22: Fino al 31/01/2027, scadenza vera.
A23: Quota delle vendite dell'anno a prezzo di lancio | C23: 0.3 | D23: 0.2 | E23: 0.15 | F23: Ipotesi.
A24: Quota delle vendite fatte da invitati (sconto 20 %) | C24: 0.15 | D24: 0.2 | E24: 0.25 | F24: Andrew Chen: il passaparola aggiunge il 25-43 % di utenti.
A25: Sconto per gli invitati | C25: 0.2 | D25: 0.2 | E25: 0.2 | F25: Proposta del documento.
A26: Quota dei Pass venduti con garanzia (+5 €) | C26: 0.1 | D26: 0.15 | E26: 0.2 | F26: Ipotesi: la garanzia parte a giugno 2027.
A27: Sovrapprezzo della garanzia | C27: 5 | D27: 5 | E27: 5 | F27: 19,99 contro 14,99.
A28: Quota dei Pass con garanzia rimborsati | C28: 0.1 | D28: 0.07 | E28: 0.05 | F28: Ipotesi: si misura nella prima estate.
A29: Quota delle vendite portate da ambassador | C29: 0.1 | D29: 0.15 | E29: 0.2 | F29: Ipotesi.
A30: Commissione degli ambassador | C30: 0.2 | D30: 0.2 | E30: 0.2 | F30: Proposta del documento.
A31: Corsi live l'anno | C31: 0 | D31: 1 | E31: 2 | F31: Solo se la lista d'attesa supera 15 iscritti.
A32: Iscritti per corso live | C32: 10 | D32: 15 | E32: 25 | F32: Ipotesi.
... A34: Costo del docente per corso (0 se lo tieni tu) | C34: 0 | D34: 80 | E34: 80 | F34: Ipotesi: 2 ore più preparazione.
A36: Pagamenti e perdite
A37: Commissione Stripe in percentuale | C37: 0.015 | D37: 0.015 | E37: 0.015 | F37: stripe.com/it/pricing: carte UE standard.
A38: Commissione Stripe fissa per pagamento | C38: 0.25 | D38: 0.25 | E38: 0.25 | F38: stripe.com/it/pricing.
A39: Recessi e contestazioni sui ricavi | C39: 0.04 | D39: 0.03 | E39: 0.02 | F39: Benchmark: 2-5 % (ricerca).
A40: Quota dei ricavi alla community (accordo PoliNetwork) | C40: 0.05 | D40: 0.05 | E40: 0.05 | F40: Proposta da negoziare; 0 se non c'è accordo.
A42: Costi fissi annui
A43: Commercialista o servizio online per forfettari | C43: 350 | D43: 350 | E43: 350 | F43: Listini 2026: 199-499 € l'anno (TaxMan, ForfettApp, FlexTax, Fiscozen).
A44: Diritto camerale (solo se iscritto al Registro imprese) | C44: 0 | D44: 0 | E44: 0 | F44: Circa 53 € l'anno se commerciante; 0 se professionista.
A45: PEC e firma digitale | C45: 40 | D45: 40 | E45: 40 | F45: Ipotesi.
A46: Dominio .it | C46: 15 | D46: 15 | E46: 15 | F46: Aruba: 11,99 € + IVA.
A47: Cloudflare (Workers a pagamento quando servono) | C47: 0 | D47: 60 | E47: 60 | F47: 5 $ al mese; gratis fino a 100.000 richieste al giorno.
A48: Termini, privacy e cookie | C48: 60 | D48: 60 | E48: 60 | F48: Generatore a pagamento più controllo; ipotesi.
...

Sheet Anno 2027
A1: Conto del primo anno di vendita: gennaio-dicembre 2027
A2: Tutte le celle sono formule sulle ipotesi. Importi in euro.
A4: Voce | C4: Prudente | D4: Base | E4: Buono
A6: Clienti
A7: Mercato del recupero (persone) | C7: =Ipotesi!$C$8*Ipotesi!$C$9*(1-Ipotesi!$C$10)+Ipotesi!$C$11 | D7: =Ipotesi!$D$8*Ipotesi!$D$9*(1-Ipotesi!$D$10)+Ipotesi!$D$11 | E7: =Ipotesi!$E$8*Ipotesi!$E$9*(1-Ipotesi!$E$10)+Ipotesi!$E$11
A8: Finiscono il diagnostico | C8: =C7*Ipotesi!$C$12 | D8: =D7*Ipotesi!$D$12 | E8: =E7*Ipotesi!$E$12
A9: Comprano il Pass (recupero) | C9: =C8*Ipotesi!$C$13 | D9: =D8*Ipotesi!$D$13 | E9: =E8*Ipotesi!$E$13
A10: Candidati che provano l'app (prevenzione) | C10: =Ipotesi!$C$16*Ipotesi!$C$17 | D10: =Ipotesi!$D$16*Ipotesi!$D$17 | E10: =Ipotesi!$E$16*Ipotesi!$E$17
A11: Comprano il Pass (prevenzione) | C11: =C10*Ipotesi!$C$18 | D11: =D10*Ipotesi!$D$18 | E11: =E10*Ipotesi!$E$18
A12: Pass venduti in totale | C12: =C9+C11 | D12: =D9+D11 | E12: =E9+E11
A13: Quota del mercato del recupero che compra | C13: =IF(C7=0,0,C9/C7) | D13: =IF(D7=0,0,D9/D7) | E13: =IF(E7=0,0,E9/E7)
A15: Ricavi
A16: Prezzo medio incassato per Pass, senza garanzia | C16: =(Ipotesi!$C$23*Ipotesi!$C$22+(1-Ipotesi!$C$23)*Ipotesi!$C$21)*(1-Ipotesi!$C$24*Ipotesi!$C$25) | D16: =(Ipotesi!$D$23*Ipotesi!$D$22+(1-Ipotesi!$D$23)*Ipotesi!$D$21)*(1-Ipotesi!$D$24*Ipotesi!$D$25) | E16: =(Ipotesi!$E$23*Ipotesi!$E$22+(1-Ipotesi!$E$23)*Ipotesi!$E$21)*(1-Ipotesi!$E$24*Ipotesi!$E$25)
A17: Ricavi dai Pass | C17: =C12*C16 | D17: =D12*D16 | E17: =E12*E16
A18: Ricavi dal sovrapprezzo della garanzia | C18: =C12*Ipotesi!$C$26*Ipotesi!$C$27 | D18: =D12*Ipotesi!$D$26*Ipotesi!$D$27 | E18: =E12*Ipotesi!$E$26*Ipotesi!$E$27
A19: Ricavi dai corsi live | C19: =Ipotesi!$C$31*Ipotesi!$C$32*Ipotesi!$C$33 | D19: =Ipotesi!$D$31*Ipotesi!$D$32*Ipotesi!$D$33 | E19: =Ipotesi!$E$31*Ipotesi!$E$32*Ipotesi!$E$33
A20: Ricavi lordi | C20: =C17+C18+C19 | D20: =D17+D18+D19 | E20: =E17+E18+E19
A22: Costi variabili
A23: Commissioni Stripe | C23: =C20*Ipotesi!$C$37+(C12+Ipotesi!$C$31*Ipotesi!$C$32)*Ipotesi!$C$38 | D23: =D20*Ipotesi!$D$37+(D12+Ipotesi!$D$31*Ipotesi!$D$32)*Ipotesi!$D$38 | E23: =E20*Ipotesi!$E$37+(E12+Ipotesi!$E$31*Ipotesi!$E$32)*Ipotesi!$E$38
A24: Recessi e contestazioni | C24: =C20*Ipotesi!$C$39 | D24: =D20*Ipotesi!$D$39 | E24: =E20*Ipotesi!$E$39
A25: Rimborsi della garanzia | C25: =C12*Ipotesi!$C$26*Ipotesi!$C$28*(C16+Ipotesi!$C$27) | D25: =D12*Ipotesi!$D$26*Ipotesi!$D$28*(D16+Ipotesi!$D$27) | E25: =E12*Ipotesi!$E$26*Ipotesi!$E$28*(E16+Ipotesi!$E$27)
A26: Commissioni agli ambassador | C26: =C17*Ipotesi!$C$29*Ipotesi!$C$30 | D26: =D17*Ipotesi!$D$29*Ipotesi!$D$30 | E26: =E17*Ipotesi!$E$29*Ipotesi!$E$30
A27: Quota alla community | C27: =C20*Ipotesi!$C$40 | D27: =D20*Ipotesi!$D$40 | E27: =E20*Ipotesi!$E$40
A28: Docenti dei corsi live | C28: =Ipotesi!$C$31*Ipotesi!$C$34 | D28: =Ipotesi!$D$31*Ipotesi!$D$34 | E28: =Ipotesi!$E$31*Ipotesi!$E$34
A29: Totale costi variabili | C29: =C23+C24+C25+C26+C27+C28 | D29: =D23+D24+D25+D26+D27+D28 | E29: =E23+E24+E25+E26+E27+E28
A31: Costi fissi
A32: Totale costi fissi | C32: =Ipotesi!$C$43+Ipotesi!$C$44+Ipotesi!$C$45+Ipotesi!$C$46+Ipotesi!$C$47+Ipotesi!$C$48+Ipotesi!$C$49+Ipotesi!$C$50 | D32: =Ipotesi!$D$43+Ipotesi!$D$44+Ipotesi!$D$45+Ipotesi!$D$46+Ipotesi!$D$47+Ipotesi!$D$48+Ipotesi!$D$49+Ipotesi!$D$50 | E32: =Ipotesi!$E$43+Ipotesi!$E$44+Ipotesi!$E$45+Ipotesi!$E$46+Ipotesi!$E$47+Ipotesi!$E$48+Ipotesi!$E$49+Ipotesi!$E$50
A34: Risultato
A35: Margine prima di contributi e imposta | C35: =C20-C29-C32 | D35: =D20-D29-D32 | E35: =E20-E29-E32
A36: Ricavi fiscali (incassi meno rimborsi e recessi) | C36: =C20-C24-C25 | D36: =D20-D24-D25 | E36: =E20-E24-E25
A37: Reddito forfettario (ricavi fiscali × coefficiente) | C37: =C36*Ipotesi!$C$54 | D37: =D36*Ipotesi!$D$54 | E37: =E36*Ipotesi!$E$54
A38: Contributi INPS se Gestione Separata (professionista) | C38: =C37*Ipotesi!$C$56 | D38: =D37*Ipotesi!$D$56 | E38: =E37*Ipotesi!$E$56
A39: Imposta sostitutiva se Gestione Separata | C39: =MAX(0,C37-C38)*Ipotesi!$C$55 | D39: =MAX(0,D37-D38)*Ipotesi!$D$55 | E39: =MAX(0,E37-E38)*Ipotesi!$E$55
A40: Utile netto in tasca se Gestione Separata | C40: =C35-C38-C39 | D40: =D35-D38-D39 | E40: =E35-E38-E39
A41: Contributi INPS se Commercianti (impresa) | C41: =(MAX(Ipotesi!$C$57,Ipotesi!$C$57+MAX(0,C37-Ipotesi!$C$59)*Ipotesi!$C$58))*(1-Ipotesi!$C$60) | D41: =(MAX(Ipotesi!$D$57,Ipotesi!$D$57+MAX(0,D37-Ipotesi!$D$59)*Ipotesi!$D$58))*(1-Ipotesi!$D$60) | E41: =(MAX(Ipotesi!$E$57,Ipotesi!$E$57+MAX(0,E37-Ipotesi!$E$59)*Ipotesi!$E$58))*(1-Ipotesi!$E$60)
A42: Imposta sostitutiva se Commercianti | C42: =MAX(0,C37-C41)*Ipotesi!$C$55 | D42: =MAX(0,D37-D41)*Ipotesi!$D$55 | E42: =MAX(0,E37-E41)*Ipotesi!$E$55
A43: Utile netto in tasca se Commercianti | C43: =C35-Ipotesi!$C$53-C41-C42 | D43: =D35-Ipotesi!$D$53-D41-D42 | E43: =E35-Ipotesi!$E$53-E41-E42
A44: Utile netto medio al mese se Gestione Separata | C44: =C40/12 | D44: =D40/12 | E44: =E40/12
A45: Quota dell'obiettivo personale coperta (Gestione Separata) | C45: =C40/Ipotesi!$C$63 | D45: =D40/Ipotesi!$D$63 | E45: =E40/Ipotesi!$E$63

Sheet Mesi
A1: Il 2027 mese per mese, scenario scelto in Ipotesi!C3
A2: I pesi (in blu) dicono in che mese cadono le vendite: devono sommare a 100 %.
A4: Voce | C4: gen | D4: feb | E4: mar | F4: apr | G4: mag | H4: giu | I4: lug | J4: ago | K4: set | L4: ott | M4: nov | N4: dic | O4: Totale
A5: Peso delle vendite di recupero | C5: 0.1 | D5: 0.14 | E5: 0.06 | F5: 0.02 | G5: 0.02 | H5: 0.05 | I5: 0.14 | J5: 0.12 | K5: 0.22 | L5: 0.08 | M5: 0.04 | N5: 0.01 | O5: =SUM(C5:N5)
A6: Peso delle vendite di prevenzione | C6: 0.1 | D6: 0.2 | E6: 0.25 | F6: 0.25 | G6: 0.2 | H6: 0 | I6: 0 | J6: 0 | K6: 0 | L6: 0 | M6: 0 | N6: 0 | O6: =SUM(C6:N6)
A7: Peso dei corsi live | C7: 0.5 | D7: 0 | E7: 0 | F7: 0 | G7: 0 | H7: 0 | I7: 0.5 | J7: 0 | K7: 0 | L7: 0 | M7: 0 | N7: 0 | O7: =SUM(C7:N7)
A9: Pass venduti | C9: =INDEX('Anno 2027'!$C$9:$E$9,Ipotesi!$D$3)*C5+INDEX('Anno 2027'!$C$11:$E$11,Ipotesi!$D$3)*C6 | D9: =INDEX('Anno 2027'!$C$9:$E$9,Ipotesi!$D$3)*D5+INDEX('Anno 2027'!$C$11:$E$11,Ipotesi!$D$3)*D6 | E9: =INDEX('Anno 2027'!$C$9:$E$9,Ipotesi!$D$3)*E5+INDEX('Anno 2027'!$C$11:$E$11,Ipotesi!$D$3)*E6 | F9: =INDEX('Anno 2027'!$C$9:$E$9,Ipotesi!$D$3)*F5+INDEX('Anno 2027'!$C$11:$E$11,Ipotesi!$D$3)*F6 | G9: =INDEX('Anno 2027'!$C$9:$E$9,Ipotesi!$D$3)*G5+INDEX('Anno 2027'!$C$11:$E$11,Ipotesi!$D$3)*G6 | H9: =INDEX('Anno 2027'!$C$9:$E$9,Ipotesi!$D$3)*H5+INDEX('Anno 2027'!$C$11:$E$11,Ipotesi!$D$3)*H6 | I9: =INDEX('Anno 2027'!$C$9:$E$9,Ipotesi!$D$3)*I5+INDEX('Anno 2027'!$C$11:$E$11,Ipotesi!$D$3)*I6 | J9: =INDEX('Anno 2027'!$C$9:$E$9,Ipotesi!$D$3)*J5+INDEX('Anno 2027'!$C$11:$E$11,Ipotesi!$D$3)*J6 | ... N9: =INDEX('Anno 2027'!$C$9:$E$9,Ipotesi!$D$3)*N5+INDEX('Anno 2027'!$C$11:$E$11,Ipotesi!$D$3)*N6 | O9: =SUM(C9:N9)
A10: Ricavi lordi | C10: =(INDEX('Anno 2027'!$C$17:$E$17,Ipotesi!$D$3)+INDEX('Anno 2027'!$C$18:$E$18,Ipotesi!$D$3))*IF(INDEX('Anno 2027'!$C$12:$E$12,Ipotesi!$D$3)=0,0,C9/INDEX('Anno 2027'!$C$12:$E$12,Ipotesi!$D$3))+INDEX('Anno 2027'!$C$19:$E$19,Ipotesi!$D$3)*C7 | D10: =(INDEX('Anno 2027'!$C$17:$E$17,Ipotesi!$D$3)+INDEX('Anno 2027'!$C$18:$E$18,Ipotesi!$D$3))*IF(INDEX('Anno 2027'!$C$12:$E$12,Ipotesi!$D$3)=0,0,D9/INDEX('Anno 2027'!$C$12:$E$12,Ipotesi!$D$3))+INDEX('Anno 2027'!$C$19:$E$19,Ipotesi!$D$3)*D7 | E10: =(INDEX('Anno 2027'!$C$17:$E$17,Ipotesi!$D$3)+INDEX('Anno 2027'!$C$18:$E$18,Ipotesi!$D$3))*IF(INDEX('Anno 2027'!$C$12:$E$12,Ipotesi!$D$3)=0,0,E9/INDEX('Anno 2027'!$C$12:$E$12,Ipotesi!$D$3))+INDEX('Anno 2027'!$C$19:$E$19,Ipotesi!$D$3)*E7 | F10: =(INDEX('Anno 2027'!$C$17:$E$17,Ipotesi!$D$3)+INDEX('Anno 2027'!$C$18:$E$18,Ipotesi!$D$3))*IF(INDEX('Anno 2027'!$C$12:$E$12,Ipotesi!$D$3)=0,0,F9/INDEX('Anno 2027'!$C$12:$E$12,Ipotesi!$D$3))+INDEX('Anno 2027'!$C$19:$E$19,Ipotesi!$D$3)*F7 | G10: =(INDEX('Anno 2027'!$C$17:$E$17,Ipotesi!$D$3)+INDEX('Anno 2027'!$C$18:$E$18,Ipotesi!$D$3))*IF(INDEX('Anno 2027'!$C$12:$E$12,Ipotesi!$D$3)=0,0,G9/INDEX('Anno 2027'!$C$12:$E$12,Ipotesi!$D$3))+INDEX('Anno 2027'!$C$19:$E$19,Ipotesi!$D$3)*G7 | H10: =(INDEX('Anno 2027'!$C$17:$E$17,Ipotesi!$D$3)+INDEX('Anno 2027'!$C$18:$E$18,Ipotesi!$D$3))*IF(INDEX('Anno 2027'!$C$12:$E$12,Ipotesi!$D$3)=0,0,H9/INDEX('Anno 2027'!$C$12:$E$12,Ipotesi!$D$3))+INDEX('Anno 2027'!$C$19:$E$19,Ipotesi!$D$3)*H7 | I10: =(INDEX('Anno 2027'!$C$17:$E$17,Ipotesi!$D$3)+INDEX('Anno 2027'!$C$18:$E$18,Ipotesi!$D$3))*IF(INDEX('Anno 2027'!$C$12:$E$12,Ipotesi!$D$3)=0,0,I9/INDEX('Anno 2027'!$C$12:$E$12,Ipotesi!$D$3))+INDEX('Anno 2027'!$C$19:$E$19,Ipotesi!$D$3)*I7 | J10: =(INDEX('Anno 2027'!$C$17:$E$17,Ipotesi!$D$3)+INDEX('Anno 2027'!$C$18:$E$18,Ipotesi!$D$3))*IF(INDEX('Anno 2027'!$C$12:$E$12,Ipotesi!$D$3)=0,0,J9/INDEX('Anno 2027'!$C$12:$E$12,Ipotesi!$D$3))+INDEX('Anno 2027'!$C$19:$E$19,Ipotesi!$D$3)*J7 | ... N10: =(INDEX('Anno 2027'!$C$17:$E$17,Ipotesi!$D$3)+INDEX('Anno 2027'!$C$18:$E$18,Ipotesi!$D$3))*IF(INDEX('Anno 2027'!$C$12:$E$12,Ipotesi!$D$3)=0,0,N9/INDEX('Anno 2027'!$C$12:$E$12,Ipotesi!$D$3))+INDEX('Anno 2027'!$C$19:$E$19,Ipotesi!$D$3)*N7 | O10: =SUM(C10:N10)
A11: Costi variabili | C11: =IF(INDEX('Anno 2027'!$C$20:$E$20,Ipotesi!$D$3)=0,0,INDEX('Anno 2027'!$C$29:$E$29,Ipotesi!$D$3)*C10/INDEX('Anno 2027'!$C$20:$E$20,Ipotesi!$D$3)) | D11: =IF(INDEX('Anno 2027'!$C$20:$E$20,Ipotesi!$D$3)=0,0,INDEX('Anno 2027'!$C$29:$E$29,Ipotesi!$D$3)*D10/INDEX('Anno 2027'!$C$20:$E$20,Ipotesi!$D$3)) | E11: =IF(INDEX('Anno 2027'!$C$20:$E$20,Ipotesi!$D$3)=0,0,INDEX('Anno 2027'!$C$29:$E$29,Ipotesi!$D$3)*E10/INDEX('Anno 2027'!$C$20:$E$20,Ipotesi!$D$3)) | F11: =IF(INDEX('Anno 2027'!$C$20:$E$20,Ipotesi!$D$3)=0,0,INDEX('Anno 2027'!$C$29:$E$29,Ipotesi!$D$3)*F10/INDEX('Anno 2027'!$C$20:$E$20,Ipotesi!$D$3)) | G11: =IF(INDEX('Anno 2027'!$C$20:$E$20,Ipotesi!$D$3)=0,0,INDEX('Anno 2027'!$C$29:$E$29,Ipotesi!$D$3)*G10/INDEX('Anno 2027'!$C$20:$E$20,Ipotesi!$D$3)) | H11: =IF(INDEX('Anno 2027'!$C$20:$E$20,Ipotesi!$D$3)=0,0,INDEX('Anno 2027'!$C$29:$E$29,Ipotesi!$D$3)*H10/INDEX('Anno 2027'!$C$20:$E$20,Ipotesi!$D$3)) | I11: =IF(INDEX('Anno 2027'!$C$20:$E$20,Ipotesi!$D$3)=0,0,INDEX('Anno 2027'!$C$29:$E$29,Ipotesi!$D$3)*I10/INDEX('Anno 2027'!$C$20:$E$20,Ipotesi!$D$3)) | J11: =IF(INDEX('Anno 2027'!$C$20:$E$20,Ipotesi!$D$3)=0,0,INDEX('Anno 2027'!$C$29:$E$29,Ipotesi!$D$3)*J10/INDEX('Anno 2027'!$C$20:$E$20,Ipotesi!$D$3)) | ... N11: =IF(INDEX('Anno 2027'!$C$20:$E$20,Ipotesi!$D$3)=0,0,INDEX('Anno 2027'!$C$29:$E$29,Ipotesi!$D$3)*N10/INDEX('Anno 2027'!$C$20:$E$20,Ipotesi!$D$3)) | O11: =SUM(C11:N11)
A12: Costi fissi (un dodicesimo) | C12: =INDEX('Anno 2027'!$C$32:$E$32,Ipotesi!$D$3)/12 | D12: =INDEX('Anno 2027'!$C$32:$E$32,Ipotesi!$D$3)/12 | E12: =INDEX('Anno 2027'!$C$32:$E$32,Ipotesi!$D$3)/12 | F12: =INDEX('Anno 2027'!$C$32:$E$32,Ipotesi!$D$3)/12 | G12: =INDEX('Anno 2027'!$C$32:$E$32,Ipotesi!$D$3)/12 | H12: =INDEX('Anno 2027'!$C$32:$E$32,Ipotesi!$D$3)/12 | I12: =INDEX('Anno 2027'!$C$32:$E$32,Ipotesi!$D$3)/12 | J12: =INDEX('Anno 2027'!$C$32:$E$32,Ipotesi!$D$3)/12 | ... N12: =INDEX('Anno 2027'!$C$32:$E$32,Ipotesi!$D$3)/12 | O12: =SUM(C12:N12)
A13: Margine del mese | C13: =C10-C11-C12 | D13: =D10-D11-D12 | E13: =E10-E11-E12 | F13: =F10-F11-F12 | G13: =G10-G11-G12 | H13: =H10-H11-H12 | I13: =I10-I11-I12 | J13: =J10-J11-J12 | ... N13: =N10-N11-N12 | O13: =SUM(C13:N13)
A14: Margine cumulato | C14: =SUM($C$13:C13) | D14: =SUM($C$13:D13) | E14: =SUM($C$13:E13) | F14: =SUM($C$13:F13) | G14: =SUM($C$13:G13) | H14: =SUM($C$13:H13) | I14: =SUM($C$13:I13) | J14: =SUM($C$13:J13) | ... N14: =SUM($C$13:N13)
A16: Contributi e imposta si pagano a saldo e acconto (giugno e novembre): qui non sono distribuiti per mese.

Sheet Tre anni
A1: 2027-2029, scenario scelto in Ipotesi!C3
A2: Ogni anno cresce la quota del mercato che prova l'app e la quota dei candidati raggiunti; dal 2029 si può aggiungere un secondo mercato. Prezzo di lancio solo nel 2027.
A4: Voce | C4: 2027 | D4: 2028 | E4: 2029
A5: Quota del mercato del recupero che prova l'app | C5: =INDEX(Ipotesi!$C$12:$E$12,Ipotesi!$D$3) | D5: =MIN(0.9,C5*(1+INDEX(Ipotesi!$C$66:$E$66,Ipotesi!$D$3))) | E5: =MIN(0.9,D5*(1+INDEX(Ipotesi!$C$66:$E$66,Ipotesi!$D$3)))
A6: Quota dei candidati che prova l'app | C6: =INDEX(Ipotesi!$C$17:$E$17,Ipotesi!$D$3) | D6: =MIN(0.5,C6*INDEX(Ipotesi!$C$67:$E$67,Ipotesi!$D$3)) | E6: =MIN(0.5,D6*INDEX(Ipotesi!$C$67:$E$67,Ipotesi!$D$3))
A7: Pass venduti (recupero) | C7: =INDEX('Anno 2027'!$C$7:$E$7,Ipotesi!$D$3)*C5*INDEX(Ipotesi!$C$13:$E$13,Ipotesi!$D$3) | D7: =INDEX('Anno 2027'!$C$7:$E$7,Ipotesi!$D$3)*D5*INDEX(Ipotesi!$C$13:$E$13,Ipotesi!$D$3) | E7: =INDEX('Anno 2027'!$C$7:$E$7,Ipotesi!$D$3)*E5*INDEX(Ipotesi!$C$13:$E$13,Ipotesi!$D$3)
A8: Pass venduti (prevenzione) | C8: =INDEX(Ipotesi!$C$16:$E$16,Ipotesi!$D$3)*C6*INDEX(Ipotesi!$C$18:$E$18,Ipotesi!$D$3) | D8: =INDEX(Ipotesi!$C$16:$E$16,Ipotesi!$D$3)*D6*INDEX(Ipotesi!$C$18:$E$18,Ipotesi!$D$3) | E8: =INDEX(Ipotesi!$C$16:$E$16,Ipotesi!$D$3)*E6*INDEX(Ipotesi!$C$18:$E$18,Ipotesi!$D$3)
A9: Prezzo medio per Pass | C9: =((INDEX(Ipotesi!$C$23:$E$23,Ipotesi!$D$3))*INDEX(Ipotesi!$C$22:$E$22,Ipotesi!$D$3)+(1-(INDEX(Ipotesi!$C$23:$E$23,Ipotesi!$D$3)))*INDEX(Ipotesi!$C$21:$E$21,Ipotesi!$D$3))*(1-INDEX(Ipotesi!$C$24:$E$24,Ipotesi!$D$3)*INDEX(Ipotesi!$C$25:$E$25,Ipotesi!$D$3)) | D9: =((0)*INDEX(Ipotesi!$C$22:$E$22,Ipotesi!$D$3)+(1-(0))*INDEX(Ipotesi!$C$21:$E$21,Ipotesi!$D$3))*(1-INDEX(Ipotesi!$C$24:$E$24,Ipotesi!$D$3)*INDEX(Ipotesi!$C$25:$E$25,Ipotesi!$D$3)) | E9: =((0)*INDEX(Ipotesi!$C$22:$E$22,Ipotesi!$D$3)+(1-(0))*INDEX(Ipotesi!$C$21:$E$21,Ipotesi!$D$3))*(1-INDEX(Ipotesi!$C$24:$E$24,Ipotesi!$D$3)*INDEX(Ipotesi!$C$25:$E$25,Ipotesi!$D$3))
A10: Ricavi lordi (Pass, garanzia, corsi) | C10: =(C7+C8)*(C9+INDEX(Ipotesi!$C$26:$E$26,Ipotesi!$D$3)*INDEX(Ipotesi!$C$27:$E$27,Ipotesi!$D$3))+INDEX('Anno 2027'!$C$19:$E$19,Ipotesi!$D$3) | D10: =(D7+D8)*(D9+INDEX(Ipotesi!$C$26:$E$26,Ipotesi!$D$3)*INDEX(Ipotesi!$C$27:$E$27,Ipotesi!$D$3))+INDEX('Anno 2027'!$C$19:$E$19,Ipotesi!$D$3) | E10: =(E7+E8)*(E9+INDEX(Ipotesi!$C$26:$E$26,Ipotesi!$D$3)*INDEX(Ipotesi!$C$27:$E$27,Ipotesi!$D$3))+INDEX('Anno 2027'!$C$19:$E$19,Ipotesi!$D$3)
A11: Ricavi da un secondo mercato | C11: =0 | D11: =0 | E11: =INDEX(Ipotesi!$C$68:$E$68,Ipotesi!$D$3)
A12: Ricavi lordi totali | C12: =C10+C11 | D12: =D10+D11 | E12: =E10+E11
A13: Costi variabili (stessa quota sui ricavi del 2027) | C13: =IF(INDEX('Anno 2027'!$C$20:$E$20,Ipotesi!$D$3)=0,0,C12*INDEX('Anno 2027'!$C$29:$E$29,Ipotesi!$D$3)/INDEX('Anno 2027'!$C$20:$E$20,Ipotesi!$D$3)) | D13: =IF(INDEX('Anno 2027'!$C$20:$E$20,Ipotesi!$D$3)=0,0,D12*INDEX('Anno 2027'!$C$29:$E$29,Ipotesi!$D$3)/INDEX('Anno 2027'!$C$20:$E$20,Ipotesi!$D$3)) | E13: =IF(INDEX('Anno 2027'!$C$20:$E$20,Ipotesi!$D$3)=0,0,E12*INDEX('Anno 2027'!$C$29:$E$29,Ipotesi!$D$3)/INDEX('Anno 2027'!$C$20:$E$20,Ipotesi!$D$3))
A14: Costi fissi | C14: =INDEX('Anno 2027'!$C$32:$E$32,Ipotesi!$D$3) | D14: =INDEX('Anno 2027'!$C$32:$E$32,Ipotesi!$D$3) | E14: =INDEX('Anno 2027'!$C$32:$E$32,Ipotesi!$D$3)
A15: Reddito forfettario | C15: =(C12*(1-INDEX(Ipotesi!$C$39:$E$39,Ipotesi!$D$3)))*INDEX(Ipotesi!$C$54:$E$54,Ipotesi!$D$3) | D15: =(D12*(1-INDEX(Ipotesi!$C$39:$E$39,Ipotesi!$D$3)))*INDEX(Ipotesi!$C$54:$E$54,Ipotesi!$D$3) | E15: =(E12*(1-INDEX(Ipotesi!$C$39:$E$39,Ipotesi!$D$3)))*INDEX(Ipotesi!$C$54:$E$54,Ipotesi!$D$3)
A16: Contributi INPS (Gestione Separata) | C16: =C15*INDEX(Ipotesi!$C$56:$E$56,Ipotesi!$D$3) | D16: =D15*INDEX(Ipotesi!$C$56:$E$56,Ipotesi!$D$3) | E16: =E15*INDEX(Ipotesi!$C$56:$E$56,Ipotesi!$D$3)
A17: Imposta sostitutiva | C17: =MAX(0,C15-C16)*INDEX(Ipotesi!$C$55:$E$55,Ipotesi!$D$3) | D17: =MAX(0,D15-D16)*INDEX(Ipotesi!$C$55:$E$55,Ipotesi!$D$3) | E17: =MAX(0,E15-E16)*INDEX(Ipotesi!$C$55:$E$55,Ipotesi!$D$3)
A18: Utile netto in tasca (Gestione Separata) | C18: =C12-C13-C14-C16-C17 | D18: =D12-D13-D14-D16-D17 | E18: =E12-E13-E14-E16-E17
A19: Quota dell'obiettivo personale coperta | C19: =C18/INDEX(Ipotesi!$C$63:$E$63,Ipotesi!$D$3) | D19: =D18/INDEX(Ipotesi!$C$63:$E$63,Ipotesi!$D$3) | E19: =E18/INDEX(Ipotesi!$C$63:$E$63,Ipotesi!$D$3)
A20: Utile netto se Commercianti (impresa) | C20: =C12-C13-C14-INDEX(Ipotesi!$C$53:$E$53,Ipotesi!$D$3)-(MAX(INDEX(Ipotesi!$C$57:$E$57,Ipotesi!$D$3),INDEX(Ipotesi!$C$57:$E$57,Ipotesi!$D$3)+MAX(0,C15-INDEX(Ipotesi!$C$59:$E$59,Ipotesi!$D$3))*INDEX(Ipotesi!$C$58:$E$58,Ipotesi!$D$3)))*(1-INDEX(Ipotesi!$C$60:$E$60,Ipotesi!$D$3))-MAX(0,C15-(MAX(INDEX(Ipotesi!$C$57:$E$57,Ipotesi!$D$3),INDEX(Ipotesi!$C$57:$E$57,Ipotesi!$D$3)+MAX(0,C15-INDEX(Ipotesi!$C$59:$E$59,Ipotesi!$D$3))*INDEX(Ipotesi!$C$58:$E$58,Ipotesi!$D$3)))*(1-INDEX(Ipotesi!$C$60:$E$60,Ipotesi!$D$3)))*INDEX(Ipotesi!$C$55:$E$55,Ipotesi!$D$3) | D20: =D12-D13-D14-INDEX(Ipotesi!$C$53:$E$53,Ipotesi!$D$3)-(MAX(INDEX(Ipotesi!$C$57:$E$57,Ipotesi!$D$3),INDEX(Ipotesi!$C$57:$E$57,Ipotesi!$D$3)+MAX(0,D15-INDEX(Ipotesi!$C$59:$E$59,Ipotesi!$D$3))*INDEX(Ipotesi!$C$58:$E$58,Ipotesi!$D$3)))*(1-INDEX(Ipotesi!$C$60:$E$60,Ipotesi!$D$3))-MAX(0,D15-(MAX(INDEX(Ipotesi!$C$57:$E$57,Ipotesi!$D$3),INDEX(Ipotesi!$C$57:$E$57,Ipotesi!$D$3)+MAX(0,D15-INDEX(Ipotesi!$C$59:$E$59,Ipotesi!$D$3))*INDEX(Ipotesi!$C$58:$E$58,Ipotesi!$D$3)))*(1-INDEX(Ipotesi!$C$60:$E$60,Ipotesi!$D$3)))*INDEX(Ipotesi!$C$55:$E$55,Ipotesi!$D$3) | E20: =E12-E13-E14-INDEX(Ipotesi!$C$53:$E$53,Ipotesi!$D$3)-(MAX(INDEX(Ipotesi!$C$57:$E$57,Ipotesi!$D$3),INDEX(Ipotesi!$C$57:$E$57,Ipotesi!$D$3)+MAX(0,E15-INDEX(Ipotesi!$C$59:$E$59,Ipotesi!$D$3))*INDEX(Ipotesi!$C$58:$E$58,Ipotesi!$D$3)))*(1-INDEX(Ipotesi!$C$60:$E$60,Ipotesi!$D$3))-MAX(0,E15-(MAX(INDEX(Ipotesi!$C$57:$E$57,Ipotesi!$D$3),INDEX(Ipotesi!$C$57:$E$57,Ipotesi!$D$3)+MAX(0,E15-INDEX(Ipotesi!$C$59:$E$59,Ipotesi!$D$3))*INDEX(Ipotesi!$C$58:$E$58,Ipotesi!$D$3)))*(1-INDEX(Ipotesi!$C$60:$E$60,Ipotesi!$D$3)))*INDEX(Ipotesi!$C$55:$E$55,Ipotesi!$D$3)

Sheet Pareggio
A1: Quanti Pass servono per coprire i costi fissi (scenario scelto)
A2: Margine per Pass = prezzo medio meno costi variabili per Pass, al netto di contributi e imposta sulla parte variabile. In COM si aggiunge il contributo minimo fisso.
A4: Voce | C4: Gestione Separata | D4: Commercianti
A5: Prezzo medio incassato per Pass | C5: =INDEX('Anno 2027'!$C$16:$E$16,Ipotesi!$D$3) | D5: =INDEX('Anno 2027'!$C$16:$E$16,Ipotesi!$D$3)
A6: Costi variabili per Pass (quota sui ricavi del 2027) | C6: =IF(INDEX('Anno 2027'!$C$20:$E$20,Ipotesi!$D$3)=0,0,C5*INDEX('Anno 2027'!$C$29:$E$29,Ipotesi!$D$3)/INDEX('Anno 2027'!$C$20:$E$20,Ipotesi!$D$3)) | D6: =C6
A7: Contributi variabili per Pass | C7: =C5*(1-INDEX(Ipotesi!$C$39:$E$39,Ipotesi!$D$3))*INDEX(Ipotesi!$C$54:$E$54,Ipotesi!$D$3)*INDEX(Ipotesi!$C$56:$E$56,Ipotesi!$D$3) | D7: =0
A8: Imposta per Pass | C8: =(C5*(1-INDEX(Ipotesi!$C$39:$E$39,Ipotesi!$D$3))*INDEX(Ipotesi!$C$54:$E$54,Ipotesi!$D$3)-C7)*INDEX(Ipotesi!$C$55:$E$55,Ipotesi!$D$3) | D8: =D5*(1-INDEX(Ipotesi!$C$39:$E$39,Ipotesi!$D$3))*INDEX(Ipotesi!$C$54:$E$54,Ipotesi!$D$3)*INDEX(Ipotesi!$C$55:$E$55,Ipotesi!$D$3)
A9: Margine netto per Pass | C9: =C5-C6-C7-C8 | D9: =D5-D6-D7-D8
A10: Costi fissi annui | C10: =INDEX('Anno 2027'!$C$32:$E$32,Ipotesi!$D$3) | D10: =INDEX('Anno 2027'!$C$32:$E$32,Ipotesi!$D$3)+INDEX(Ipotesi!$C$53:$E$53,Ipotesi!$D$3)
A11: Contributo INPS fisso annuo | C11: =0 | D11: =INDEX(Ipotesi!$C$57:$E$57,Ipotesi!$D$3)*(1-INDEX(Ipotesi!$C$60:$E$60,Ipotesi!$D$3))
A12: Pass l'anno per andare in pari | C12: =IF(C9<=0,0,(C10+C11)/C9) | D12: =IF(D9<=0,0,(D10+D11)/D9)
A13: Pass l'anno per l'obiettivo personale | C13: =IF(C9<=0,0,(C10+C11+INDEX(Ipotesi!$C$63:$E$63,Ipotesi!$D$3))/C9) | D13: =IF(D9<=0,0,(D10+D11+INDEX(Ipotesi!$C$63:$E$63,Ipotesi!$D$3))/D9)
A14: Confronto: mercato del recupero l'anno (persone) | C14: =INDEX('Anno 2027'!$C$7:$E$7,Ipotesi!$D$3) | D14: =INDEX('Anno 2027'!$C$7:$E$7,Ipotesi!$D$3)
